Workbook

Sheet Leggimi
B2: Il ladro di sabbia — Prototipo di bilanciamento economico (v3, ancorato a dati reali)
B4: A cosa serve questo file
B5: Testare a numeri il loop centrale (azioni -> costo tempo-figlia / effetto sabbia-padre) PRIMA di scrivere codice o arte, per capire se il ritmo e le scelte 'tirano' nella direzione giusta.
B7: Come è strutturato
B8: Foglio 'Azioni': elenco delle azioni. Il costo/guadagno in sabbia ora si basa su un valore economico realistico in euro (colonna D), convertito in ore tramite il tasso mediano in B2 del foglio stesso.
B9: Foglio 'Simulatore Run': simula una run scegliendo una sequenza di azioni (celle blu), i totali si aggiornano da soli.
B11: Legenda colori
B12: Testo blu | C12: cella modificabile (input tuo)
B13: Testo nero | C13: formula, non toccare (si aggiorna da sola)
B14: Sfondo giallo | C14: assunzione/parametro chiave da tarare
B16: METODOLOGIA di questa ricalibrazione (v3)
B17: 1) ANCORA ECONOMICA: 1 ora di sabbia 'mediana' = 14,9 € (salario mediano lordo orario nell'UE, Eurostat Structure of Earnings Survey 2022 - dato piu' recente disponibile, la rilevazione e' quadriennale). E' una MEDIANA, non una media: resistente agli stipendi outlier, com'era richiesto. Il tasso e' impostato nella cella B2 del foglio Azioni: cambialo per ricalibrare l'intera economia con un solo numero.
B18: 2) LAVORO ONESTO = quasi un pareggio. Se lavori a salario mediano, il costo tempo e l'effetto sabbia si equivalgono quasi (al netto di una stima del 25% di cuneo fiscale su lavoro regolare). Non e' un errore: e' realistico che un lavoro onesto a paga mediana a malapena copra il costo della vita, il che rende narrativamente piu' comprensibile perche' il protagonista si rivolga al crimine.
B19: 3) IL CRIMINE NON PAGA LE TASSE, MA IN REALTA' RENDE POCO: i dati FBI mostrano che la rapina in banca 'media' (quella con un semplice biglietto di richiesta) frutta solo 4.200-9.600$, molto meno di quanto il cinema suggerisca (fonte: FBI Bank Crime Statistics / UCR Robbery reports). Ho quindi riclassificato la rapina 'da sportello' come un colpo di entita' modesta (foglio Azioni, 'Rapina a un negozio'), e riservato numeri realmente enormi solo al 'grande colpo' pianificato con l'intera rete di contatti - coerente con i rari colpi-record della storia reale (decine/centinaia di milioni), non con la rapina media.
B20: 4) SEQUESTRO DI PERSONA: il riscatto mediano globale e' single-cifra-decine-di-migliaia di $ (circa 27-29 mila $, fonte Control Risks), ma i casi di famiglie facoltose (non ultra-miliardarie) tipicamente superano il milione. Ho usato 1.000.000 € come stima per 'l'erede di una famiglia ricca' del gioco, un valore intermedio plausibile per questo profilo di bersaglio.
B21: 5) Ogni valore economico non derivato da una statistica pubblica e' comunque una STIMA plausibile basata sugli ordini di grandezza reali (es. prezzo di un'arma sul mercato nero, incasso di una serata di poker clandestino): sono annotate come 'stima' nella colonna Fonte/nota, da considerarsi indicative, non dati ufficiali.
B22: 6) Il Rischio % resta di riferimento, non simulato con dadi/RAND in questo prototipo deterministico.
B23: 7) Costo Tempo-Figlia resta legato alla durata narrativa dell'azione (max 168 ore, la settimana), NON e' derivato dal tasso economico: rappresenta tempo di gioco che passa, non ricchezza.
B24: 8) Tempo-Figlia parte da 168 ore (una settimana), Sabbia-Padre da 24 ore: il padre ha una riserva personale minima e fragile, coerente con l'aver dato quasi tutto per la figlia.
B25: 9) 1 anno = 8.760 ore (colonna F del foglio Azioni la converte in automatico), per leggere a colpo d'occhio la scala dei numeri grandi.
B26: 10) REGOLA FONDAMENTALE DEL MONDO: la sabbia non e' un oggetto fisico ne' un saldo impersonale in un caveau. Esiste solo dentro le persone e si trasferisce solo con il consenso del donatore (anche se estorto con minacce o tortura). Una banca non e' un forziere da scassinare: e' fatta di persone il cui compito e' accumulare sabbia per l'istituto e cederla su richiesta autorizzata - rapinarla significa coercere quelle persone specifiche. 'Sabbia sporca' e' solo un modo di dire per 'ottenuta illecitamente', non una sostanza diversa da ripulire su un mercato a parte. L'azione 'Vendere sabbia sporca a un compratore di alto livello' e' stata corretta per questo motivo (vedi colonna Fonte/nota).

Sheet Azioni
A1: PARAMETRI ECONOMICI (tarabili)
A2: Salario mediano lordo UE, €/ora (Eurostat SES 2022) | B2: 14.9
A3: Ore in un anno (per colonna anni equivalenti) | B3: 8760
A5: Azione | B5: Categoria | C5: Costo Tempo-Figlia (ore) | D5: Valore economico stimato (€) | E5: Effetto Sabbia-Padre (ore) | F5: Effetto Sabbia-Padre (anni equiv.) | G5: Rischio % (riferimento) | H5: Moralita' | I5: Fonte / assunzione
A6: Turno di lavoro onesto (8h, salario mediano) | B6: Lavoro | C6: 8 | D6: 89 | E6: =D6/$B$2 -> 5.9731544 | F6: =E6/$B$3 -> 0.00068186694 | G6: 0 | H6: Pulita | I6: 8h x 14,9€ mediano, netto -25% cuneo fiscale stimato
A7: Turno doppio / straordinario (+25%) | B7: Lavoro | C7: 16 | D7: 224 | E7: =D7/$B$2 -> 15.033557 | F7: =E7/$B$3 -> 0.0017161595 | G7: 0.05 | H7: Pulita (logorante) | I7: 16h x 14,9€ x1,25 maggiorazione, netto -25%
A8: Settimana di lavoro nero con un caporale | B8: Lavoro | C8: 72 | D8: 698 | E8: =D8/$B$2 -> 46.845638 | F8: =E8/$B$3 -> 0.0053476755 | G8: 0.2 | H8: Ambigua | I8: Paga informale ~65% della mediana, non tassata (nessuna detrazione, ma nessuna tutela)
A9: Lavoretto di sicurezza per un vecchio contatto | B9: Lavoro | C9: 24 | D9: 536 | E9: =D9/$B$2 -> 35.973154 | F9: =E9/$B$3 -> 0.0041065245 | G9: 0.15 | H9: Ambigua | I9: Competenze rare pagate ~150% mediana, in nero
A10: Consulenza sicurezza per un'azienda | B10: Lavoro | C10: 48 | D10: 1341 | E10: =D10/$B$2 -> 90 | F10: =E10/$B$3 -> 0.010273973 | G10: 0.05 | H10: Pulita/ambigua | I10: Tariffa da consulente specializzato ~250% mediana, tassata
A11: Vendere anni futuri a un'agenzia di prestiti-vita | B11: Lavoro | C11: 2 | D11: 652620 | E11: =D11/$B$2 -> 43800 | F11: =E11/$B$3 -> 5 | G11: 0 | H11: Estrema (debito esistenziale) | I11: Prestito equivalente a 5 anni di sabbia, non un salario: e' un debito enorme da restituire, non un guadagno pulito
A12: Fare da cavia per un esperimento clandestino | B12: Lavoro | C12: 6 | D12: 1500 | E12: =D12/$B$2 -> 100.67114 | F12: =E12/$B$3 -> 0.011492139 | G12: 0.35 | H12: Sporca | I12: Stima compenso studi clinici rischiosi non regolamentati
A13: Mendicare in strada | B13: Mendicare | C13: 8 | D13: 20 | E13: =D13/$B$2 -> 1.3422819 | F13: =E13/$B$3 -> 0.00015322853 | G13: 0.05 | H13: Pulita/neutra | I13: Stima elemosina media giornaliera in una grande citta'
A14: Rovistare tra i rifiuti in zone ricche | B14: Mendicare | C14: 5 | D14: 10 | E14: =D14/$B$2 -> 0.67114094 | F14: =E14/$B$3 -> 7.6614263e-05 | G14: 0.05 | H14: Neutra | I14: Stima valore oggetti riciclabili trovati
A15: Esibirsi per strada (musica) | B15: Mendicare | C15: 6 | D15: 40 | E15: =D15/$B$2 -> 2.6845638 | F15: =E15/$B$3 -> 0.00030645705 | G15: 0 | H15: Pulita | I15: Stima incasso medio busking
A16: Vendere oggetti personali (fede nuziale) | B16: Mendicare | C16: 1 | D16: 200 | E16: =D16/$B$2 -> 13.422819 | F16: =E16/$B$3 -> 0.0015322853 | G16: 0 | H16: Ambigua (costo emotivo) | I16: Prezzo medio oro usato
A17: Fingersi malato per elemosina mirata | B17: Mendicare | C17: 4 | D17: 35 | E17: =D17/$B$2 -> 2.3489933 | F17: =E17/$B$3 -> 0.00026814992 | G17: 0.1 | H17: Ambigua | I17: Stima
... A56: Fare benzina | B56: Bisogni | C56: 0 | D56: -20 | E56: =D56/$B$2 -> -1.3422819 | F56: =E56/$B$3 -> -0.00015322853 | G56: 0 | H56: Neutra | I56: Pieno parziale stimato
A57: Riposare (dormire) | B57: Bisogni | C57: 8 | D57: 0 | E57: =D57/$B$2 -> 0 | F57: =E57/$B$3 -> 0 | G57: 0 | H57: Neutra (saltabile)
A58: Chiedere un favore importante a un vecchio boss | B58: Relazioni | C58: 4 | D58: 1000 | E58: =D58/$B$2 -> 67.114094 | F58: =E58/$B$3 -> 0.0076614263 | G58: 0.15 | H58: Ambigua (debito futuro) | I58: Stima
A59: Corrompere un poliziotto | B59: Corruzione | C59: 0 | D59: -500 | E59: =D59/$B$2 -> -33.557047 | F59: =E59/$B$3 -> -0.0038307131 | G59: 0 | H59: Ambigua | I59: Stima bustarella per evitare un arresto minore
A60: Corrompere un giudice per far cadere un'accusa | B60: Corruzione | C60: 2 | D60: -20000 | E60: =D60/$B$2 -> -1342.2819 | F60: =E60/$B$3 -> -0.15322853 | G60: 0.05 | H60: Sporca | I60: Corruzione di alto livello, importi molto piu' alti di un poliziotto
A61: Fare l'informatore per la polizia (tradimento) | B61: Tradimento | C61: 6 | D61: 100000 | E61: =D61/$B$2 -> 6711.4094 | F61: =E61/$B$3 -> 0.76614263 | G61: 0.6 | H61: Estrema | I61: Stima compenso per informazioni decisive contro l'organizzazione
A62: Donare sabbia a un bisognoso | B62: Altruismo | C62: 1 | D62: -50 | E62: =D62/$B$2 -> -3.3557047 | F62: =E62/$B$3 -> -0.00038307131 | G62: 0 | H62: Pulita | I62: Stima
A63: Visitare la figlia in ospedale | B63: Narrativo | C63: 2 | D63: 0 | E63: =D63/$B$2 -> 0 | F63: =E63/$B$3 -> 0 | G63: 0 | H63: Pulita
A64: Riattivare un vecchio contatto della rete criminale | B64: Relazioni | C64: 4 | D64: 0 | E64: =D64/$B$2 -> 0 | F64: =E64/$B$3 -> 0 | G64: 0.1 | H64: Ambigua (apre azioni di alto livello) | I64: Nessun guadagno diretto, e' un prerequisito narrativo
A65: Ripagare un vecchio debito d'onore | B65: Relazioni | C65: 2 | D65: -5000 | E65: =D65/$B$2 -> -335.57047 | F65: =E65/$B$3 -> -0.038307131 | G65: 0 | H65: Ambigua | I65: Stima importo debito
A67: Aggiungi altre righe qui sotto per nuove azioni (il Simulatore le trova automaticamente, range fino a riga 150). Cambia il salario mediano in B2 per ricalibrare TUTTA l'economia con un solo numero.

Sheet Simulatore Run
A1: Simulatore di run — scegli una sequenza di azioni e guarda l'esito
A3: Tempo iniziale figlia (ore) - 168 = una settimana | B3: 168
A4: Sabbia iniziale padre (ore) - riserva volutamente minima | B4: 24
A6: Turno | B6: Azione (scrivi esattamente come nel foglio Azioni) | C6: Costo Tempo (ore) | D6: Effetto Sabbia (ore) | E6: Tempo-Figlia rimasto (ore) | F6: Sabbia-Padre accumulata (ore) | G6: Sabbia-Padre (anni equiv.) | H6: Giorno (circa, 24h=1gg) | I6: Stato
A7: 1 | B7: Turno di lavoro onesto (8h, salario mediano) | C7: =IFERROR(INDEX(Azioni!$C$6:$C$150,MATCH(B7,Azioni!$A$6:$A$150,0)),"") -> 8 | D7: =IFERROR(INDEX(Azioni!$E$6:$E$150,MATCH(B7,Azioni!$A$6:$A$150,0)),"") -> 5.9731544 | E7: =$B$3-C7 -> 160 | F7: =$B$4+D7 -> 29.973154 | G7: =F7/8760 -> 0.003421593 | H7: =INT(($B$3-E7)/24)+1 -> 1 | I7: =IF(E7<0,"GAME OVER - tempo scaduto (figlia)",IF(F7<0,"GAME OVER - il padre muore","OK")) -> OK
A8: 2 | B8: Comprare un pasto | C8: =IFERROR(INDEX(Azioni!$C$6:$C$150,MATCH(B8,Azioni!$A$6:$A$150,0)),"") -> 1 | D8: =IFERROR(INDEX(Azioni!$E$6:$E$150,MATCH(B8,Azioni!$A$6:$A$150,0)),"") -> -0.53691275 | E8: =E7-C8 -> 159 | F8: =F7+D8 -> 29.436242 | G8: =F8/8760 -> 0.0033603016 | H8: =INT(($B$3-E8)/24)+1 -> 1 | I8: =IF(E8<0,"GAME OVER - tempo scaduto (figlia)",IF(F8<0,"GAME OVER - il padre muore","OK")) -> OK
A9: 3 | B9: Riposare (dormire) | C9: =IFERROR(INDEX(Azioni!$C$6:$C$150,MATCH(B9,Azioni!$A$6:$A$150,0)),"") -> 8 | D9: =IFERROR(INDEX(Azioni!$E$6:$E$150,MATCH(B9,Azioni!$A$6:$A$150,0)),"") -> 0 | E9: =E8-C9 -> 151 | F9: =F8+D9 -> 29.436242 | G9: =F9/8760 -> 0.0033603016 | H9: =INT(($B$3-E9)/24)+1 -> 1 | I9: =IF(E9<0,"GAME OVER - tempo scaduto (figlia)",IF(F9<0,"GAME OVER - il padre muore","OK")) -> OK
A10: 4 | B10: Poker in una bisca di quartiere | C10: =IFERROR(INDEX(Azioni!$C$6:$C$150,MATCH(B10,Azioni!$A$6:$A$150,0)),"") -> 2 | D10: =IFERROR(INDEX(Azioni!$E$6:$E$150,MATCH(B10,Azioni!$A$6:$A$150,0)),"") -> 10.067114 | E10: =E9-C10 -> 149 | F10: =F9+D10 -> 39.503356 | G10: =F10/8760 -> 0.0045095155 | H10: =INT(($B$3-E10)/24)+1 -> 1 | I10: =IF(E10<0,"GAME OVER - tempo scaduto (figlia)",IF(F10<0,"GAME OVER - il padre muore","OK")) -> OK
A11: 5 | B11: Vendere oggetti personali (fede nuziale) | C11: =IFERROR(INDEX(Azioni!$C$6:$C$150,MATCH(B11,Azioni!$A$6:$A$150,0)),"") -> 1 | D11: =IFERROR(INDEX(Azioni!$E$6:$E$150,MATCH(B11,Azioni!$A$6:$A$150,0)),"") -> 13.422819 | E11: =E10-C11 -> 148 | F11: =F10+D11 -> 52.926174 | G11: =F11/8760 -> 0.0060418007 | H11: =INT(($B$3-E11)/24)+1 -> 1 | I11: =IF(E11<0,"GAME OVER - tempo scaduto (figlia)",IF(F11<0,"GAME OVER - il padre muore","OK")) -> OK
A12: 6 | B12: Piccolo furto (scippo) | C12: =IFERROR(INDEX(Azioni!$C$6:$C$150,MATCH(B12,Azioni!$A$6:$A$150,0)),"") -> 1 | D12: =IFERROR(INDEX(Azioni!$E$6:$E$150,MATCH(B12,Azioni!$A$6:$A$150,0)),"") -> 10.067114 | E12: =E11-C12 -> 147 | F12: =F11+D12 -> 62.993289 | G12: =F12/8760 -> 0.0071910147 | H12: =INT(($B$3-E12)/24)+1 -> 1 | I12: =IF(E12<0,"GAME OVER - tempo scaduto (figlia)",IF(F12<0,"GAME OVER - il padre muore","OK")) -> OK
A13: 7 | B13: Riattivare un vecchio contatto della rete criminale | C13: =IFERROR(INDEX(Azioni!$C$6:$C$150,MATCH(B13,Azioni!$A$6:$A$150,0)),"") -> 4 | D13: =IFERROR(INDEX(Azioni!$E$6:$E$150,MATCH(B13,Azioni!$A$6:$A$150,0)),"") -> 0 | E13: =E12-C13 -> 143 | F13: =F12+D13 -> 62.993289 | G13: =F13/8760 -> 0.0071910147 | H13: =INT(($B$3-E13)/24)+1 -> 2 | I13: =IF(E13<0,"GAME OVER - tempo scaduto (figlia)",IF(F13<0,"GAME OVER - il padre muore","OK")) -> OK
A14: 8 | B14: Comprare i piani di sicurezza di una banca | C14: =IFERROR(INDEX(Azioni!$C$6:$C$150,MATCH(B14,Azioni!$A$6:$A$150,0)),"") -> 6 | D14: =IFERROR(INDEX(Azioni!$E$6:$E$150,MATCH(B14,Azioni!$A$6:$A$150,0)),"") -> -536.91275 | E14: =E13-C14 -> 137 | F14: =F13+D14 -> -473.91946 | G14: =F14/8760 -> -0.054100395 | H14: =INT(($B$3-E14)/24)+1 -> 2 | I14: =IF(E14<0,"GAME OVER - tempo scaduto (figlia)",IF(F14<0,"GAME OVER - il padre muore","OK")) -> GAME OVER - il padre muore
A15: 9 | B15: Comprare un pasto | C15: =IFERROR(INDEX(Azioni!$C$6:$C$150,MATCH(B15,Azioni!$A$6:$A$150,0)),"") -> 1 | D15: =IFERROR(INDEX(Azioni!$E$6:$E$150,MATCH(B15,Azioni!$A$6:$A$150,0)),"") -> -0.53691275 | E15: =E14-C15 -> 136 | F15: =F14+D15 -> -474.45638 | G15: =F15/8760 -> -0.054161687 | H15: =INT(($B$3-E15)/24)+1 -> 2 | I15: =IF(E15<0,"GAME OVER - tempo scaduto (figlia)",IF(F15<0,"GAME OVER - il padre muore","OK")) -> GAME OVER - il padre muore
A16: 10 | B16: Comprare un'arma dal fornitore di fiducia | C16: =IFERROR(INDEX(Azioni!$C$6:$C$150,MATCH(B16,Azioni!$A$6:$A$150,0)),"") -> 0 | D16: =IFERROR(INDEX(Azioni!$E$6:$E$150,MATCH(B16,Azioni!$A$6:$A$150,0)),"") -> -53.691275 | E16: =E15-C16 -> 136 | F16: =F15+D16 -> -528.14765 | G16: =F16/8760 -> -0.060290828 | H16: =INT(($B$3-E16)/24)+1 -> 2 | I16: =IF(E16<0,"GAME OVER - tempo scaduto (figlia)",IF(F16<0,"GAME OVER - il padre muore","OK")) -> GAME OVER - il padre muore
A17: 11 | B17: Riposare (dormire) | C17: =IFERROR(INDEX(Azioni!$C$6:$C$150,MATCH(B17,Azioni!$A$6:$A$150,0)),"") -> 8 | D17: =IFERROR(INDEX(Azioni!$E$6:$E$150,MATCH(B17,Azioni!$A$6:$A$150,0)),"") -> 0 | E17: =E16-C17 -> 128 | F17: =F16+D17 -> -528.14765 | G17: =F17/8760 -> -0.060290828 | H17: =INT(($B$3-E17)/24)+1 -> 2 | I17: =IF(E17<0,"GAME OVER - tempo scaduto (figlia)",IF(F17<0,"GAME OVER - il padre muore","OK")) -> GAME OVER - il padre muore
A18: 12 | B18: Minacciare un passante | C18: =IFERROR(INDEX(Azioni!$C$6:$C$150,MATCH(B18,Azioni!$A$6:$A$150,0)),"") -> 2 | D18: =IFERROR(INDEX(Azioni!$E$6:$E$150,MATCH(B18,Azioni!$A$6:$A$150,0)),"") -> 13.422819 | E18: =E17-C18 -> 126 | F18: =F17+D18 -> -514.72483 | G18: =F18/8760 -> -0.058758542 | H18: =INT(($B$3-E18)/24)+1 -> 2 | I18: =IF(E18<0,"GAME OVER - tempo scaduto (figlia)",IF(F18<0,"GAME OVER - il padre muore","OK")) -> GAME OVER - il padre muore
A19: 13 | B19: Vendere refurtiva al proprio fence | C19: =IFERROR(INDEX(Azioni!$C$6:$C$150,MATCH(B19,Azioni!$A$6:$A$150,0)),"") -> 2 | D19: =IFERROR(INDEX(Azioni!$E$6:$E$150,MATCH(B19,Azioni!$A$6:$A$150,0)),"") -> 10.067114 | E19: =E18-C19 -> 124 | F19: =F18+D19 -> -504.65772 | G19: =F19/8760 -> -0.057609329 | H19: =INT(($B$3-E19)/24)+1 -> 2 | I19: =IF(E19<0,"GAME OVER - tempo scaduto (figlia)",IF(F19<0,"GAME OVER - il padre muore","OK")) -> GAME OVER - il padre muore
... A25: 19 | B25: Visitare la figlia in ospedale | C25: =IFERROR(INDEX(Azioni!$C$6:$C$150,MATCH(B25,Azioni!$A$6:$A$150,0)),"") -> 2 | D25: =IFERROR(INDEX(Azioni!$E$6:$E$150,MATCH(B25,Azioni!$A$6:$A$150,0)),"") -> 0 | E25: =E24-C25 -> 15 | F25: =F24+D25 -> 201306.89 | G25: =F25/8760 -> 22.980238 | H25: =INT(($B$3-E25)/24)+1 -> 7 | I25: =IF(E25<0,"GAME OVER - tempo scaduto (figlia)",IF(F25<0,"GAME OVER - il padre muore","OK")) -> OK
A27: RIEPILOGO FINALE
A28: Tempo-Figlia rimasto alla fine (ore) | B28: =E25 -> 15
A29: Sabbia-Padre accumulata alla fine (ore) | B29: =F25 -> 201306.89
A30: Sabbia-Padre accumulata alla fine (anni) | B30: =F25/8760 -> 22.980238
A31: Sabbia donata alla figlia (ore) - decisione tua | B31: 0
A32: Sabbia tenuta per se' (ore) | B32: =B30-B31 -> 22.980238

Sheet Endgame
A1: ENDGAME — Tracce, Risorse, Sottotrame, Sinergie
A2: Sistema per rendere raggiungibile - ma molto raro - il traguardo dei 100 anni per il padre + 100 per la figlia in una singola settimana. Vedi il documento Word, sezione dedicata, per la spiegazione narrativa completa e i risultati della simulazione.
A4: 1. LE 5 RISORSE
A5: Risorsa | B5: Tipo | C5: Effetto in gioco | D5: Come sale | E5: Come scende
A6: Attenzione Polizia | B6: Globale (per run) | C6: Alza il rischio % di tutte le azioni illegali; oltre 50 indagini attive, oltre 75 retata imminente | D6: Azioni criminali/rischiose | E6: Tempo passato senza agire, corruzione dedicata
A7: Rivalita' Criminale | B7: Globale (per run) | C7: Alza il rischio di agguati/tradimenti; oltre 50 un rivale si muove, oltre 75 agguato pianificato | D7: Salire di rango, soppiantare boss/gestori | E7: Tempo, favori/tributi ai rivali
A8: Fama Pubblica | B8: Globale (per run) | C8: Alza il rischio di ogni azione criminale contemporanea (piu' sei visibile, piu' sei osservato) | D8: Ranghi pubblici/legittimi (Direttore, Burattinaio, Capo di culto tollerato) | E8: Basso profilo, tempo
A9: Karma | B9: PERSISTENTE tra le run (unica) | C9: Alza frequenza/gravita' degli eventi negativi casuali; e' cio' che la voce della madre intende con 'la sabbia non dimentica' | D9: Azioni immorali (peso preso dalla colonna Moralita': Ambigua +1, Sporca +2, Molto sporca +3, Estrema +5) | E9: Azioni pulite/altruiste (-1); un patto con lo Stregatto (prezzo alto)
A10: Fede (del Culto / della Setta) | B10: Locale, una per traccia religiosa | C10: Determina l'avanzamento di rango nelle tracce Religiosa e Occulto; le due Fedi sono in tensione tra loro | D10: Rituali/devozione coerenti con quella fede | E10: Azioni della fede rivale, tempo di inattivita'
A13: 2. LE 7 TRACCE NORMALI (sblocco sempre via malavita/rete di contatti)
A14: Traccia | B14: Rango | C14: Costo Tempo-Figlia (ore) | D14: Effetto Sabbia-Padre (ore) | E14: Rischio % | F14: Note
A15: Lavoro | B15: Rango 1 - Caposquadra | C15: 20 | D15: 6040.3 | E15: 0.15 | F15: ~90.000€: piccola somma ottenuta ricattando il capo attuale, non ancora un vero schema di appropriazione indebita
A16: Lavoro | B16: Rango 2 - Direttore | C16: 28 | D16: 93959.7 | E16: 0.1 | F16: ~1,4M€: ordine di grandezza di uno schema di appropriazione indebita dirigenziale di media durata (perdita mediana dirigenti 337.000$ per singolo caso, fino a 2,2M$ su 5 anni - fonti ACFE/Hiscox/BERO Group). Sblocca 'Intascare la percentuale della squadra'
A17: Criminale | B17: Rango 1 - Luogotenente | C17: 24 | D17: 8724.8 | E17: 0.3 | F17: ~130.000€: prima quota di fiducia ottenuta dall'organizzazione. Prova di lealta'
A18: Criminale | B18: Rango 2 - Boss | C18: 32 | D18: 124161.1 | E18: 0.45 | F18: ~1,85M€: stima per ordine di grandezza, incasso settimanale aggregato di un'organizzazione criminale di medio livello. Tradisci/elimini/soppianti il vecchio boss
A19: Politica | B19: Rango 1 - Fixer di un politico | C19: 28 | D19: 17449.7 | E19: 0.2 | F19: ~260.000€: primo compenso per un favore politico procurato con materiale compromettente
A20: Politica | B20: Rango 2 - Burattinaio | C20: 32 | D20: 140939.6 | E20: 0.35 | F20: ~2,1M€: stima per ordine di grandezza da scandali di corruzione politica locale documentati. Controlli di fatto le sue decisioni
A21: Azzardo | B21: Rango 1 - Giocatore riconosciuto | C21: 20 | D21: 17449.7 | E21: 0.2 | F21: ~260.000€: prima vincita significativa che apre l'accesso ai tavoli alti
A22: Azzardo | B22: Rango 2 - Gestore di una bisca | C22: 28 | D22: 130872.5 | E22: 0.4 | F22: ~1,95M€: stima su incassi di bische clandestine di alto livello sequestrate in operazioni di polizia reali. Soppianti il gestore rivale
A23: Bancaria | B23: Rango 1 - Insider corrotto | C23: 28 | D23: 26174.5 | E23: 0.15 | F23: ~390.000€: primo pagamento per informazioni bancarie riservate
A24: Bancaria | B24: Rango 2 - Direttore di filiale in pugno | C24: 36 | D24: 191275.2 | E24: 0.3 | F24: ~2,85M€: ordine di grandezza di uno schema di appropriazione indebita bancaria pluriennale (perdita mediana schemi da 10 anni 5,4M$ - fonte BERO Group). Ricatto pesante e continuativo
A25: Religiosa (indulgenze) | B25: Rango 1 - Predicatore/venditore di reliquie false | C25: 20 | D25: 17449.7 | E25: 0.1 | F25: ~260.000€: prime offerte raccolte con il racket delle indulgenze
A26: Religiosa (indulgenze) | B26: Rango 2 - Capo di un culto tollerato | C26: 28 | D26: 130872.5 | E26: 0.25 | F26: ~1,95M€: stima per ordine di grandezza da casi reali documentati di frode religiosa/culto di alto profilo. I fedeli cedono sabbia per la 'salvezza' (Fede del Culto)
... A28: Occulto (setta satanica) | B28: Rango 2 - Capo della setta | C28: 32 | D28: 130872.5 | E28: 0.45 | F28: ~1,95M€: stesso ordine di grandezza della traccia Religiosa. Flusso alto e costante (Fede della Setta); nessun legame con gli Eterni
A30: Nota: i costi qui sono in ore-tempo (asse Tempo-Figlia) e gli effetti in ore-sabbia (asse Sabbia-Padre), stessa logica del foglio Azioni. TUNING FINALE completato: valori ancorati a dati reali dove disponibili (schemi di appropriazione indebita dirigenziale/bancaria - fonti ACFE, Hiscox, BERO Group) e a stime per ordine di grandezza da casi documentati per il resto (criminalita' organizzata, corruzione politica, bische clandestine, frodi religiose), dichiarate esplicitamente come tali nella colonna Note.
A33: 3. LE 3 TRACCE BONUS (narrative, nessun valore economico fisso)
A34: Eterni | B34: Scoperta opzionale tramite side quest rare. Nessun guadagno diretto: e' la sottotrama cosmologica del gioco (sezione 7 del documento).
A35: Rete di scienziati criminali | B35: Sbloccata da contatti criminali + fare da cavia per esperimenti. Cercano di estrarre sabbia senza consenso: minaccia di sistema parallela agli Eterni, non una fonte di reddito normale.
A36: Magica (perche' solo gli umani scambiano sabbia) | B36: Indipendente da Eterni e Occulto. Traccia di lore/scoperta, non di reddito.
A39: 4. LE 10 SOTTOTRAME (valori ricalibrati dopo la simulazione)
A40: Sottotrama | B40: Costo Tempo-Figlia (ore) | C40: Effetto Sabbia-Padre (ore) | D40: Rischio % | E40: Note
A41: Il tesoro del vecchio boss | B41: 48 | C41: 124161.1 | D41: 0.5 | E41: ~1,85M€: stima per ordine di grandezza, risparmio criminale accumulato in anni da un boss deceduto. Sabbia affidata a una persona di fiducia, da rintracciare
A42: L'asta dei secoli | B42: 40 | C42: 157718.1 | D42: 0.55 | E42: ~2,35M€: stima su ordine di grandezza di aste di lusso/clandestine di altissimo profilo. Richiede documenti falsi di alta qualita' + un invito
A43: L'ultima donazione | B43: 24 | C43: 87248.3 | D43: 0.3 | E43: ~1,3M€: stima su patrimoni netti individuali di fascia alta in punto di morte. Sostituisce 'Il registro dei non reclamati'
A44: Il patto con l'usuraio della mezzanotte | B44: 16 | C44: 177852.3 | D44: 0.2 | E44: ~2,65M€: prestito equivalente, non un guadagno pulito - e' un debito enorme da restituire, non uno stipendio. Ribilanciato rispetto alla prima versione (era sproporzionato)
A45: La cripta della setta degli eterni | B45: 72 | C45: 265100.7 | D45: 0.65 | E45: ~3,95M€: ordine di grandezza di grandi patrimoni ecclesiastici/settari accumulati nei secoli, documentati storicamente in casi analoghi. Dopo questa azione il rischio sale per il resto della run
A46: Il grande torneo dei senza-tempo | B46: 48 | C46: 211409.4 | D46: 0.55 | E46: ~3,15M€: stima, montepremi aggregato di piu' round di scommesse estreme. Ritiro possibile in ogni momento
A47: Il crollo della casata [nome da assegnare] | B47: 72 | C47: 298657.7 | D47: 0.6 | E47: ~4,45M€: ordine di grandezza di grandi patrimoni familiari aristocratici europei storici documentati. A piu' fasi: prove, ricatto, colpo finale
A48: La fuga dal purgatorio dei debitori | B48: 48 | C48: 104026.8 | D48: 0.45 | E48: ~1,55M€: stima, debiti aggregati dei prigionieri liberati/derubati. Di piu' se non liberi gli altri prigionieri
A49: Il tavolo dei senza fondo | B49: 24 | C49: 191275.2 | D49: 0.55 | E49: ~2,85M€: stima, puntate aggregate di un tavolo clandestino ad altissimo livello. Accesso solo su garanzia di un boss
...
